Workbook

Sheet Test Cases
A1: TC_ID | B1: Module | C1: Req_ID | D1: Title | E1: Test_Type | F1: Scenario | G1: Technique | H1: Priority | I1: Preconditions | J1: Test_Data | K1: Steps | L1: Expected_Result | N1: Status | O1: Notes | P1: Design_Status | Q1: Actual_Result | R1: Bug_ID | S1: Tester | T1: Executed_Date
A2: TC-FLT-001 | B2: 01. Bộ lọc kỳ & thuế | C2: REQ-UI-01;REQ-UI-02 | D2: Kiểm tra khối bộ lọc hiển thị đủ Kỳ xem, Từ ngày – Đến ngày, Store, Client Advisor, Giá trị tiền | E2: UI | F2: Positive | G2: CL | H2: P3 | I2: 1. Theo SETUP-01: đăng nhập U-CRM 2. Theo SETUP-07: môi trường có dữ liệu ~100 store | J2: - | K2: 1. Mở menu Dashboard, vào màn hình Dashboard Doanh thu & Đơn hàng 2. Quan sát khối bộ lọc trên cùng màn hình | L2: 2. Có nhóm Kỳ xem gồm 5 nút "Hôm nay", "Tuần này", "Tháng này", "Tháng trước", "Năm này" - Có ô Từ ngày – Đến ngày kèm icon lịch, bộ chọn Store, bộ lọc Client Advisor - Góc phải có nhóm Giá trị tiền với 2 nút "Sau thuế" và "Trước thuế" | M2: No | N2: Not Run | O2: Mockup image1–3: Kỳ xem, Từ ngày – Đến ngày, Store, Giá trị tiền | P2: Ready
A3: TC-FLT-002 | B3: 01. Bộ lọc kỳ & thuế | C3: REQ-UI-01 | D3: Kiểm tra preset Hôm nay đặt kỳ đúng 1 ngày là ngày hiện tại | E3: Functional | F3: Positive | G3: EP | H3: P2 | I3: 1. Theo SETUP-01: đăng nhập U-CRM | J3: - | K3: 1. Mở menu Dashboard, vào màn hình Dashboard Doanh thu & Đơn hàng 2. Bấm nút "Hôm nay" | L3: 2. Nút Hôm nay ở trạng thái đang chọn; Từ ngày = Đến ngày = ngày hiện tại (dd/mm/yyyy) - Khối biểu đồ Sales theo thời gian không vẽ cột (kỳ 1 ngày) | M3: Candidate | N3: Not Run | P3: Ready
A4: TC-FLT-003 | B4: 01. Bộ lọc kỳ & thuế | C4: REQ-UI-01 | D4: Kiểm tra preset Tuần này đặt kỳ từ Thứ Hai của tuần hiện tại đến hôm nay | E4: Functional | F4: Positive | G4: EP | H4: P2 | I4: 1. Theo SETUP-01: đăng nhập U-CRM | J4: - | K4: 1. Mở menu Dashboard, vào màn hình Dashboard Doanh thu & Đơn hàng 2. Bấm nút "Tuần này" | L4: 2. Từ ngày = Thứ Hai của tuần chứa hôm nay; Đến ngày = hôm nay | M4: Candidate | N4: Not Run | O4: [Giả định AS-05] ngày kết thúc của Tuần này. Nếu hôm nay là Thứ Hai: kỳ 1 ngày | P4: Needs Clarification (AS-05)
A5: TC-FLT-004 | B5: 01. Bộ lọc kỳ & thuế | C5: REQ-UI-01 | D5: Kiểm tra preset Tháng này đặt kỳ từ ngày 01 của tháng hiện tại đến hôm nay | E5: Functional | F5: Positive | G5: EP | H5: P2 | I5: 1. Theo SETUP-01: đăng nhập U-CRM | J5: - | K5: 1. Mở menu Dashboard, vào màn hình Dashboard Doanh thu & Đơn hàng 2. Bấm nút "Tháng này" | L5: 2. Từ ngày = 01/<tháng hiện tại>/<năm>; Đến ngày = hôm nay (ví dụ nguồn: Tháng này 01/10–14/10 khi hôm nay 14/10) | M5: Candidate | N5: Not Run | P5: Ready
A6: TC-FLT-005 | B6: 01. Bộ lọc kỳ & thuế | C6: REQ-UI-01 | D6: Kiểm tra preset Tháng trước đặt kỳ trọn tháng dương lịch liền trước | E6: Functional | F6: Positive | G6: EP | H6: P2 | I6: 1. Theo SETUP-01: đăng nhập U-CRM | J6: - | K6: 1. Mở menu Dashboard, vào màn hình Dashboard Doanh thu & Đơn hàng 2. Bấm nút "Tháng trước" | L6: 2. Từ ngày = ngày 01 của tháng trước; Đến ngày = ngày cuối của tháng trước (ví dụ nguồn: 01/09–30/09) | M6: Candidate | N6: Not Run | P6: Ready
A7: TC-FLT-006 | B7: 01. Bộ lọc kỳ & thuế | C7: REQ-UI-01 | D7: Kiểm tra preset Năm này đặt kỳ từ 01/01 năm hiện tại đến hôm nay | E7: Functional | F7: Positive | G7: EP | H7: P2 | I7: 1. Theo SETUP-01: đăng nhập U-CRM | J7: - | K7: 1. Mở menu Dashboard, vào màn hình Dashboard Doanh thu & Đơn hàng 2. Bấm nút "Năm này" | L7: 2. Từ ngày = 01/01/<năm hiện tại>; Đến ngày = hôm nay (ví dụ nguồn: Năm này 01/01–14/10) | M7: Candidate | N7: Not Run | P7: Ready
A8: TC-FLT-007 | B8: 01. Bộ lọc kỳ & thuế | C8: REQ-UI-01 | D8: Kiểm tra chọn khoảng Từ ngày – Đến ngày 01/09/2026 – 30/09/2026 áp dụng cho mọi khối | E8: Functional | F8: Positive | G8: EP | H8: P1 | I8: 1. Theo SETUP-01: đăng nhập U-CRM 2. Theo SETUP-08: có truy vấn Sales, Transactions toàn Tam Sơn kỳ 01/09–30/09/2026 | J8: Từ ngày: 01/09/2026; Đến ngày: 30/09/2026 | K8: 1. Mở menu Dashboard, vào màn hình Dashboard Doanh thu & Đơn hàng 2. Nhập Từ ngày 01/09/2026, Đến ngày 30/09/2026 trên lịch chọn khoảng 3. Xem thẻ Sales, Transactions và biểu đồ Sales theo thời gian | L8: 2. Ô hiển thị 01/09/2026 – 30/09/2026 3. Sales và Transactions bằng kết quả truy vấn SETUP-08 cùng kỳ; biểu đồ có 30 cột từ 01/09 đến 30/09 | M8: Candidate | N8: Not Run | O8: Truy vấn đối soát: tính đơn 0đ [Giả định AS-01], tính đơn B2B [Cần xác nhận Q-16], loại ecom [Giả định AS-09]; trạng thái nút preset khi khoảng trùng Tháng trước: Q-45 (không kiểm) | P8: Needs Clarification (Q-16, Q-45, AS-01, AS-09)
A9: TC-FLT-008 | B9: 01. Bộ lọc kỳ & thuế | C9: REQ-UI-01 | D9: Kiểm tra chấp nhận khoảng 366 ngày (biên tối đa) 01/01/2025 – 01/01/2026 | E9: Validation | F9: Boundary | G9: BVA | H9: P2 | I9: 1. Theo SETUP-01: đăng nhập U-CRM | J9: Từ ngày: 01/01/2025; Đến ngày: 01/01/2026 (366 ngày) | K9: 1. Mở menu Dashboard, vào màn hình Dashboard Doanh thu & Đơn hàng 2. Nhập Từ ngày 01/01/2025, Đến ngày 01/01/2026 trên lịch chọn khoảng | L9: 2. Kỳ được áp dụng, không có thông báo lỗi; ô hiển thị 01/01/2025 – 01/01/2026; KPI và biểu đồ tính lại (biểu đồ tự chọn Tháng, 13 cột) | M9: Candidate | N9: Not Run | P9: Ready
A10: TC-FLT-009 | B10: 01. Bộ lọc kỳ & thuế | C10: REQ-UI-01 | D10: Kiểm tra chặn khoảng 367 ngày: báo lỗi và giữ nguyên kỳ đang xem | E10: Validation | F10: Boundary | G10: BVA | H10: P2 | I10: 1. Theo SETUP-01: đăng nhập U-CRM | J10: Kỳ ban đầu: Tháng này; Từ ngày: 01/01/2025; Đến ngày: 02/01/2026 (367 ngày) | K10: 1. Mở menu Dashboard, vào màn hình Dashboard Doanh thu & Đơn hàng 2. Bấm nút "Tháng này" và ghi lại giá trị thẻ Sales 3. Nhập Từ ngày 01/01/2025, Đến ngày 02/01/2026 trên lịch chọn khoảng | L10: 3. Hiển thị thông báo lỗi về khoảng vượt tối đa 366 ngày [Cần xác nhận Q-07] - Kỳ vẫn là Tháng này; ô Từ ngày – Đến ngày, thẻ Sales và biểu đồ giữ nguyên như bước 2 | M10: Candidate | N10: Not Run | O10: Nội dung lỗi: [Cần xác nhận Q-07] | P10: Needs Clarification (Q-07)
A11: TC-FLT-010 | B11: 01. Bộ lọc kỳ & thuế | C11: REQ-UI-01 | D11: Kiểm tra kỳ mặc định khi mở dashboard lần đầu là Tháng này | E11: Functional | F11: Positive | G11: EP | H11: P3 | I11: 1. Theo SETUP-01: đăng nhập U-CRM 2. Phiên đăng nhập mới (chưa mở dashboard trong phiên) | J11: - | K11: 1. Mở menu Dashboard, vào màn hình Dashboard Doanh thu & Đơn hàng | L11: 1. Nút Tháng này ở trạng thái đang chọn; Từ ngày = 01 tháng hiện tại, Đến ngày = hôm nay | M11: Candidate | N11: Not Run | O11: [Giả định AS-05] theo mockup | P11: Needs Clarification (AS-05)
A12: TC-FLT-011 | B12: 01. Bộ lọc kỳ & thuế | C12: REQ-UI-02 | D12: Kiểm tra cách nhìn thuế mặc định khi mở dashboard là Sau thuế | E12: Functional | F12: Positive | G12: EP | H12: P2 | I12: 1. Theo SETUP-01: đăng nhập U-CRM 2. Phiên đăng nhập mới | J12: - | K12: 1. Mở menu Dashboard, vào màn hình Dashboard Doanh thu & Đơn hàng | L12: 1. Nút "Sau thuế" ở trạng thái đang chọn; thẻ Sales, AOV, Avg Spending/Customer gắn nhãn "Sau thuế" | M12: Candidate | N12: Not Run | O12: [Giả định AS-04] theo mockup; OQ-SPM-15 | P12: Needs Clarification (AS-04)
A13: TC-FLT-012 | B13: 01. Bộ lọc kỳ & thuế | C13: FR-SPM-009 | D13: Kiểm tra đổi Sau thuế sang Trước thuế không gọi lại API dữ liệu và hai số cùng snapshot | E13: Integration | F13: Positive | G13: EG | H13: P2 | I13: 1. Theo SETUP-01: đăng nhập U-CRM 2. Theo SETUP-09: mở DevTools tab Network | J13: Kỳ: Tháng trước | K13: 1. Mở menu Dashboard, vào màn hình Dashboard Doanh thu & Đơn hàng 2. Bấm "Tháng trước", chờ tải xong, xoá log Network 3. Ghi lại Sales sau thuế và dòng phụ Trước thuế trên thẻ Sales 4. Bấm "Trước thuế" | L13: 4. Tab Network không phát sinh request tải lại dữ liệu chỉ số - Số chính thẻ Sales bằng giá trị dòng phụ Trước thuế ghi ở bước 3; dòng phụ mới bằng số Sau thuế ở bước 3 | M13: Candidate | N13: Not Run | O13: AC-SPM-009-09 | P13: Ready
A14: TC-SCOPE-001 | B14: 02. Phạm vi dữ liệu & phân quyền | C14: FR-SPM-001 | D14: Kiểm tra Store Manager 2 store chỉ thấy số liệu ST1 + ST2, không gồm ST3 | E14: Security | F14: Positive | G14: PERM | H14: P1 | I14: 1. Theo SETUP-01: đăng nhập U-SM12 2. Theo SETUP-02 (ST1, ST2, ST3 có đơn ngày D) | J14: Kỳ: D – D | K14: 1. Mở menu Dashboard, vào màn hình Dashboard Doanh thu & Đơn hàng 2. Nhập Từ ngày D, Đến ngày D trên lịch chọn khoảng 3. Xem bộ chọn Store và các thẻ KPI | L14: 3. Bộ chọn Store chỉ có ST1, ST2 (đã chọn cả hai) - Transactions = 7 (ST1: 5, ST2: 2); Sales sau thuế = 46 600 000; không có đơn OC1, OC2 của ST3 | M14: passed | N14: Not Run | O14: AC-SPM-001-01 | P14: Ready
A15: TC-SCOPE-002 | B15: 02. Phạm vi dữ liệu & phân quyền | C15: FR-SPM-001 | D15: Kiểm tra Store Manager chọn riêng ST2 thì mọi chỉ số chỉ tính trên ST2 | E15: Functional | F15: Positive | G15: EP | H15: P1 | I15: 1. Theo SETUP-01: đăng nhập U-SM12 2. Theo SETUP-02 | J15: Kỳ: D – D; Store: ST2 | K15: 1. Mở menu Dashboard, vào màn hình Dashboard Doanh thu & Đơn hàng 2. Nhập Từ ngày D, Đến ngày D trên lịch chọn khoảng 3. Mở bộ chọn Store, chỉ chọn ST2 | L15: 3. Sales sau thuế = 4 000 000; Transactions = 2; Total Customers = 2; Coupon % = 50.0%; AOV = 2 000 000; UPT = 0.50; Frequency = 1.00; Avg Spending = 2 000 000 | M15: passed | N15: Not Run | O15: AC-SPM-001-02 | P15: Ready
A16: TC-SCOPE-003 | B16: 02. Phạm vi dữ liệu & phân quyền | C16: FR-SPM-001 | D16: Kiểm tra Client Advisor chỉ thấy bill mình đứng tên, không thấy số cấp store | E16: Security | F16: Positive | G16: PERM | H16: P1 | I16: 1. Theo SETUP-01: đăng nhập U-CA-A 2. Theo SETUP-02 | J16: Kỳ: D – D | K16: 1. Mở menu Dashboard, vào màn hình Dashboard Doanh thu & Đơn hàng 2. Nhập Từ ngày D, Đến ngày D trên lịch chọn khoảng 3. Xem thẻ Transactions và các khối trên màn hình | L16: 3. Transactions = 4 (O1, O2, O5, O6); không có O3 (chỉ CA-B đứng tên) - Không có số cấp store ST1 (Transactions store = 5) ở bất kỳ khối nào; bộ chọn Store/lọc CA không cho xem phạm vi khác [Cần xác nhận Q-40] | N16: Not Run | O16: AC-SPM-001-03; [Cần xác nhận Q-40] hiển thị bộ lọc ở mức Cá nhân | P16: Needs Clarification (Q-40)
A17: TC-SCOPE-004 | B17: 02. Phạm vi dữ liệu & phân quyền | C17: FR-SPM-001 | D17: Kiểm tra bill có 2 Client Advisor đứng tên được tính trọn cho cả hai, tổng 2 người lớn hơn store | E17: Functional | F17: Edge | G17: DT | H17: P1 | I17: 1. Theo SETUP-01: tài khoản U-CA-A, U-CA-B, U-SM12 2. Theo SETUP-02 | J17: Kỳ: D – D; bill chung: O2 | K17: 1. Đăng nhập U-CA-A, mở menu dashboard, vào màn hình dashboard doanh thu & đơn hàng, chọn kỳ D – D, ghi Transactions 2. Đăng xuất, đăng nhập U-CA-B, chọn kỳ D – D, ghi Transactions 3. Đăng xuất, đăng nhập U-SM12, chọn kỳ D – D, chọn riêng ST1, ghi Transactions | L17: 1. CA-A: Transactions = 4 (gồm O2) 2. CA-B: Transactions = 2 (gồm O2) 3. ST1: Transactions = 5; tổng CA-A + CA-B = 6 > 5 vì O2 tính trọn cho cả hai | N17: Not Run | O17: AC-SPM-001-04; Sales mức Cá nhân phụ thuộc cách gán đơn trả [Cần xác nhận Q-31] nên dùng Transactions | P17: Needs Clarification (Q-31)
A18: TC-SCOPE-005 | B18: 02. Phạm vi dữ liệu & phân quyền | C18: FR-SPM-001 | D18: Kiểm tra CRM Team thấy số toàn Tam Sơn khớp truy vấn đối soát | E18: Integration | F18: Positive | G18: PERM | H18: P1 | I18: 1. Theo SETUP-01: đăng nhập U-CRM 2. Theo SETUP-07: môi trường có dữ liệu ~100 store 3. Theo SETUP-08: truy vấn Σ total đơn bán CO, đơn trả, số đơn bán toàn bộ store (trừ ecom) kỳ 01/09–30/09/2026 | J18: Kỳ: 01/09/2026 – 30/09/2026 | K18: 1. Mở menu Dashboard, vào màn hình Dashboard Doanh thu & Đơn hàng 2. Nhập Từ ngày 01/09/2026, Đến ngày 30/09/2026 trên lịch chọn khoảng 3. So sánh thẻ Sales sau thuế, Transactions với kết quả truy vấn | L18: 3. Sales sau thuế = Σ total đơn bán − Σ total đơn trả của mọi store; Transactions = số đơn bán hợp lệ của mọi store | M18: passed | N18: Not Run | O18: Ecom loại khỏi truy vấn theo [Giả định AS-09]; đơn 0đ tính là transaction [Giả định AS-01]; đơn B2B tính [Cần xác nhận Q-16] | P18: Needs Clarification (Q-16, AS-01, AS-09)
A19: TC-SCOPE-006 | B19: 02. Phạm vi dữ liệu & phân quyền | C19: FR-SPM-001 | D19: Kiểm tra tài khoản nhiều Position nhận phạm vi lớn nhất được cấp | E19: Security | F19: Positive | G19: PERM | H19: P2 | I19: 1. Theo SETUP-01: đăng nhập U-MULTI (Store Manager ST1 + Retail Manager Brand BR-1; BR-1 gồm ST1, ST3) | J19: - | K19: 1. Mở menu Dashboard, vào màn hình Dashboard Doanh thu & Đơn hàng 2. Mở bộ chọn Store | L19: 2. Danh sách gồm toàn bộ store Brand BR-1 (ST1, ST3 và store BR-1 khác) — phạm vi lớn nhất là Retail Manager BR-1; mặc định chọn tất cả; không có ST2 (BR-2) | M19: passed | N19: Not Run | P19: Ready
A20: TC-SCOPE-007 | B20: 02. Phạm vi dữ liệu & phân quyền | C20: FR-SPM-001;FR-SPM-003 | D20: Kiểm tra đơn đã huỷ (VO) không vào Sales và Transactions | E20: Functional | F20: Negative | G20: EP | H20: P1 | I20: 1. Theo SETUP-01: đăng nhập U-SM12 2. Theo SETUP-02 (O7 3 000 000 đã chuyển VO) | J20: Kỳ: D – D; Store: ST1 | K20: 1. Mở menu Dashboard, vào màn hình Dashboard Doanh thu & Đơn hàng 2. Nhập Từ ngày D, Đến ngày D trên lịch chọn khoảng 3. Mở bộ chọn Store, chỉ chọn ST1 | L20: 3. Transactions = 5 (không có O7); Sales sau thuế = 42 600 000 (không cộng 3 000 000 của O7) | N20: Not Run | O20: AC-SPM-001-07 | P20: Ready
A21: TC-SCOPE-008 | B21: 02. Phạm vi dữ liệu & phân quyền | C21: FR-SPM-001 | D21: Kiểm tra đơn nháp/đang xử lý chưa hoàn tất không vào Sales và Transactions | E21: Functional | F21: Negative | G21: EP | H21: P1 | I21: 1. Theo SETUP-01: đăng nhập U-SM12 2. Theo SETUP-02 (O8 2 000 000 để trạng thái chưa hoàn tất) | J21: Kỳ: D – D; Store: ST1 | K21: 1. Mở menu Dashboard, vào màn hình Dashboard Doanh thu & Đơn hàng 2. Nhập Từ ngày D, Đến ngày D trên lịch chọn khoảng 3. Mở bộ chọn Store, chỉ chọn ST1 | L21: 3. Transactions = 5 (không có O8); Sales sau thuế = 42 600 000 (không cộng 2 000 000 của O8) | N21: Not Run | O21: AC-SPM-001-07 | P21: Ready
A22: TC-SCOPE-009 | B22: 02. Phạm vi dữ liệu & phân quyền | C22: FR-SPM-001 | D22: Kiểm tra đơn từ warehouse ecom 1000332 không xuất hiện ở phạm vi store nào | E22: Functional | F22: Negative | G22: EP | H22: P1 | I22: 1. Theo SETUP-01: đăng nhập U-SM12 2. Theo SETUP-03: 1 đơn CO warehouse 1000332, total 7 000 000, hoàn tất ngày E | J22: Kỳ: E – E | K22: 1. Mở menu Dashboard, vào màn hình Dashboard Doanh thu & Đơn hàng 2. Nhập Từ ngày E, Đến ngày E trên lịch chọn khoảng 3. Xem Sales và Transactions của ST1, ST2 và bảng Theo Store | L22: 3. Không store nào có thêm 7 000 000 / 1 đơn; số liệu bằng số trước khi đẩy đơn ecom | N22: Not Run | O22: AC-SPM-001-06 | P22: Blocked (SETUP-03)
A23: TC-SCOPE-010 | B23: 02. Phạm vi dữ liệu & phân quyền | C23: FR-SPM-001 | D23: Kiểm tra đơn ecom không được tính ở mức Toàn Tam Sơn | E23: Functional | F23: Negative | G23: EP | H23: P2 | I23: 1. Theo SETUP-01: đăng nhập U-CRM 2. Theo SETUP-03: 1 đơn CO warehouse 1000333, total 7 000 000, hoàn tất ngày E | J23: Kỳ: E – E | K23: 1. Mở menu Dashboard, vào màn hình Dashboard Doanh thu & Đơn hàng 2. Nhập Từ ngày E, Đến ngày E trên lịch chọn khoảng 3. So sánh Sales toàn Tam Sơn với truy vấn SETUP-08 có và không có đơn ecom | L23: 3. Sales toàn Tam Sơn bằng giá trị không gồm đơn ecom [Giả định AS-09] | N23: Not Run | O23: [Giả định AS-09] OQ-SPM-06 | P23: Blocked (SETUP-03, AS-09)
A24: TC-SCOPE-011 | B24: 02. Phạm vi dữ liệu & phân quyền | C24: FR-SPM-001 | D24: Kiểm tra đơn hoàn tất 23:50 ngày 30/09 (UTC+7) thuộc kỳ tháng 9 | E24: Functional | F24: Boundary | G24: BVA | H24: P2 | I24: 1. Theo SETUP-01: đăng nhập U-SM12 2. Theo SETUP-03: đơn CO tại ST2, total 1 234 000, hoàn tất 30/09/2026 23:50:00 +07:00 | J24: Kỳ: 01/09/2026 – 30/09/2026 | K24: 1. Mở menu Dashboard, vào màn hình Dashboard Doanh thu & Đơn hàng 2. Nhập Từ ngày 01/09/2026, Đến ngày 30/09/2026 trên lịch chọn khoảng 3. Mở bộ chọn Store, chỉ chọn ST2 | L24: 3. Sales và Transactions của ST2 gồm đơn này (+1 234 000; +1) | N24: Not Run | O24: AC-SPM-001-05 | P24: Blocked (SETUP-03)
A25: TC-SCOPE-012 | B25: 02. Phạm vi dữ liệu & phân quyền | C25: FR-SPM-001 | D25: Kiểm tra đơn hoàn tất 00:00:30 ngày 01/10 (UTC+7) không thuộc kỳ tháng 9 | E25: Functional | F25: Boundary | G25: BVA | H25: P2 | I25: 1. Theo SETUP-01: đăng nhập U-SM12 2. Theo SETUP-03: đơn CO tại ST2, total 4 321 000, hoàn tất 01/10/2026 00:00:30 +07:00 | J25: Kỳ 1: 01/09/2026 – 30/09/2026; Kỳ 2: 01/10/2026 – 01/10/2026 | K25: 1. Mở menu Dashboard, vào màn hình Dashboard Doanh thu & Đơn hàng 2. Mở bộ chọn Store, chỉ chọn ST2 3. Nhập Từ ngày 01/09/2026, Đến ngày 30/09/2026 trên lịch chọn khoảng 4. Nhập Từ ngày 01/10/2026, Đến ngày 01/10/2026 trên lịch chọn khoảng | L25: 3. Sales tháng 9 của ST2 không gồm 4 321 000 4. Sales ngày 01/10 của ST2 gồm 4 321 000 | N25: Not Run | P25: Blocked (SETUP-03)
A26: TC-SCOPE-013 | B26: 02. Phạm vi dữ liệu & phân quyền | C26: FR-SPM-001 | D26: Kiểm tra gọi API số liệu với store ngoài phạm vi (ST3) bị từ chối | E26: Security | F26: Negative | G26: PERM | H26: P1 | I26: 1. Theo SETUP-01: đăng nhập U-SM12 2. Theo SETUP-09: DevTools tab Network | J26: Store ngoài phạm vi: ST3 | K26: 1. Mở menu Dashboard, vào màn hình Dashboard Doanh thu & Đơn hàng 2. Trong Network, copy request lấy số liệu dashboard (Copy as fetch/cURL) 3. Sửa tham số store thành ID của ST3, gửi lại bằng phiên của U-SM12 | L26: 3. Hệ thống từ chối: response không chứa Sales/Transactions của ST3 (lỗi phân quyền hoặc dữ liệu rỗng), không trả số của ST3 | N26: Not Run | O26: AC-SPM-001-08; BR-SPM-001 áp dụng ở tầng truy vấn | P26: Ready
A27: TC-SCOPE-014 | B27: 02. Phạm vi dữ liệu & phân quyền | C27: FR-SPM-001 | D27: Kiểm tra Client Advisor gọi API lấy số store hoặc số của CA khác bị từ chối | E27: Security | F27: Negative | G27: PERM | H27: P1 | I27: 1. Theo SETUP-01: đăng nhập U-CA-A 2. Theo SETUP-09: DevTools tab Network | J27: Phạm vi thử: ST1 cấp store; nhân viên U-CA-B | K27: 1. Mở menu Dashboard, vào màn hình Dashboard Doanh thu & Đơn hàng 2. Copy request lấy số liệu dashboard 3. Sửa tham số phạm vi thành cấp store ST1, gửi lại 4. Sửa tham số nhân viên thành U-CA-B, gửi lại | L27: 3. Không trả số cấp store ST1 4. Không trả số của U-CA-B | N27: Not Run | O27: BR-SPM-001 | P27: Ready
A28: TC-SCOPE-015 | B28: 02. Phạm vi dữ liệu & phân quyền | C28: FR-SPM-001;FR-SPM-011 | D28: Kiểm tra bộ chọn Store không cho tìm hoặc chọn store ngoài phạm vi | E28: Security | F28: Negative | G28: PERM | H28: P1 | I28: 1. Theo SETUP-01: đăng nhập U-SM12 | J28: Từ khoá: tên ST3 | K28: 1. Mở menu Dashboard, vào màn hình Dashboard Doanh thu & Đơn hàng 2. Mở bộ chọn Store, gõ tên ST3 vào ô tìm kiếm | L28: 2. Không có kết quả ST3; danh sách chỉ có thể chứa ST1, ST2 | N28: Not Run | O28: BR-SPM-020: không mở rộng ngoài phạm vi | P28: Ready
A29: TC-SCOPE-016 | B29: 02. Phạm vi dữ liệu & phân quyền | C29: FR-SPM-001 | D29: Kiểm tra đơn không có nhân viên đứng tên tính ở mức store nhưng không ở mức Cá nhân | E29: Functional | F29: Edge | G29: EP | H29: P2 | I29: 1. Theo SETUP-01: U-SM12, U-CA-A, U-CA-B 2. Theo SETUP-03: đơn CO tại ST1, list_employees = [], total 2 222 000, hoàn tất ngày E | J29: Kỳ: E – E | K29: 1. Đăng nhập U-SM12, mở dashboard, chọn kỳ E – E, chọn riêng ST1 2. Đăng nhập lần lượt U-CA-A, U-CA-B, chọn kỳ E – E | L29: 1. Sales ST1 gồm 2 222 000, Transactions gồm đơn này 2. Không Client Advisor nào có đơn này trong Sales/Transactions | N29: Not Run | O29: AC-SPM-001-09 | P29: Blocked (SETUP-03)
A30: TC-SCOPE-017 | B30: 02. Phạm vi dữ liệu & phân quyền | C30: REQ-UI-05;FR-SPM-011 | D30: Kiểm tra giao diện vai trò Cá nhân chỉ có biểu đồ thời gian và thẻ giải thích thay bảng | E30: UI | F30: Positive | G30: PERM | H30: P2 | I30: 1. Theo SETUP-01: đăng nhập U-CA-A | J30: Kỳ: Tháng này | K30: 1. Mở menu Dashboard, vào màn hình Dashboard Doanh thu & Đơn hàng 2. Cuộn qua khối biểu đồ và khối bảng | L30: 2. Có biểu đồ Sales theo thời gian; không có panel Xếp hạng Top 10 / Bottom 10 - Không có bảng breakdown; thay bằng thẻ giải thích nội dung "tính trọn bill mình đứng tên" | N30: Not Run | P30: Ready
A31: TC-SCOPE-018 | B31: 02. Phạm vi dữ liệu & phân quyền | C31: FR-SPM-001 | D31: Kiểm tra đăng xuất rồi đăng nhập vai trò khác không giữ phạm vi store cũ | E31: Security | F31: Edge | G31: EG | H31: P2 | I31: 1. Theo SETUP-01: U-CRM, U-SM12 | J31: - | K31: 1. Đăng nhập U-CRM, mở dashboard, chọn riêng 1 store ngoài ST1/ST2 2. Đăng xuất 3. Đăng nhập U-SM12 trên cùng trình duyệt, mở dashboard | L31: 3. Bộ chọn Store chỉ có ST1, ST2 và đang chọn cả hai; không còn store chọn ở bước 1 | M31: passed | N31: Not Run | P31: Ready
A32: TC-SCOPE-019 | B32: 02. Phạm vi dữ liệu & phân quyền | C32: FR-SPM-009 | D32: Kiểm tra đơn đồng bộ chậm từ HUB thuộc kỳ cũ làm thay đổi số của kỳ cũ | E32: Integration | F32: Edge | G32: EG | H32: P3 | I32: 1. Theo SETUP-01: đăng nhập U-SM12 2. Theo SETUP-03: đẩy qua HUB 1 đơn CO tại ST2, total 3 333 000, ngày hoàn tất 15/09/2026, sau khi đã ghi số tháng 9 | J32: Kỳ: 01/09/2026 – 30/09/2026 | K32: 1. Mở menu Dashboard, vào màn hình Dashboard Doanh thu & Đơn hàng 2. Nhập Từ ngày 01/09/2026, Đến ngày 30/09/2026 trên lịch chọn khoảng 3. Mở bộ chọn Store, chỉ chọn ST2, ghi Sales 4. Đẩy đơn chậm qua HUB, chờ đồng bộ, tải lại dashboard với cùng kỳ | L32: 4. Sales tháng 9 của ST2 tăng 3 333 000, Transactions tăng 1 (không có ngày chốt số liệu) | N32: Not Run | P32: Blocked (SETUP-03)
A33: TC-SCOPE-020 | B33: 02. Phạm vi dữ liệu & phân quyền | C33: FR-SPM-001 | D33: Kiểm tra mức Cá nhân không phụ thuộc PIC: bill của khách có PIC là CA-A nhưng chỉ CA-B đứng tên chỉ tính cho CA-B | E33: Security | F33: Edge | G33: DT | H33: P1 | I33: 1. Theo SETUP-01: tài khoản U-CA-A, U-CA-B 2. Theo SETUP-05: khách KP có PIC = U-CA-A tại ST1 3. Theo SETUP-11: ngày G (U-CA-A, U-CA-B không có đơn khác ngày G), tạo tại ST1 bill BP của KP, total 3 000 000, chỉ U-CA-B đứng tên | J33: Kỳ: G – G; bill BP 3 000 000; đứng tên: U-CA-B; PIC của khách: U-CA-A | K33: 1. Mở menu Dashboard, vào màn hình Dashboard Doanh thu & Đơn hàng bằng U-CA-A 2. Nhập Từ ngày G, Đến ngày G trên lịch chọn khoảng 3. Đăng xuất, đăng nhập U-CA-B, mở dashboard, nhập kỳ G – G | L33: 2. U-CA-A: Transactions = 0, Sales = 0 (bill BP không tính dù U-CA-A là PIC của khách) 3. U-CA-B: Transactions = 1, Sales = 3 000 000 | N33: Not Run | O33: Review R-08; BR-SPM-002 | P33: Ready
A34: TC-SCOPE-021 | B34: 02. Phạm vi dữ liệu & phân quyền | C34: FR-SPM-001;FR-SPM-011 | D34: Kiểm tra Store Manager chỉ được gán 1 store: nhãn là tên store, xếp hạng Client Advisor, không có tab Theo Store | E34: Functional | F34: Positive | G34: PERM | H34: P2 | I34: 1. Theo SETUP-01: đăng nhập U-SM1 (Store Manager chỉ ST1) 2. Theo SETUP-02 | J34: Kỳ: D – D | K34: 1. Mở menu Dashboard, vào màn hình Dashboard Doanh thu & Đơn hàng 2. Nhập Từ ngày D, Đến ngày D trên lịch chọn khoảng 3. Mở bộ chọn Store, bỏ chọn ST1 4. Xem panel xếp hạng, bảng breakdown và bộ lọc Client Advisor | L34: 2. Nhãn bộ chọn Store là tên ST1; Sales = 42 600 000, Transactions = 5 3. ST1 vẫn được chọn (không bỏ được store cuối) 4. Panel xếp hạng Client Advisor của ST1; bảng không có tab Theo Store, có tab Theo Client Advisor; bộ lọc Client Advisor khả dụng (1 store ≤ 5) | N34: Not Run | O34: Review R-09; BR-SPM-020…023 | P34: Ready
A35: TC-SCOPE-022 | B35: 02. Phạm vi dữ liệu & phân quyền | C35: FR-SPM-001 | D35: Kiểm tra biên dưới của kỳ: đơn 00:00:00 ngày đầu kỳ thuộc kỳ, đơn 23:59:59 ngày liền trước không thuộc | E35: Functional | F35: Boundary | G35: BVA | H35: P2 | I35: 1. Theo SETUP-01: đăng nhập U-SM12 2. Theo SETUP-03: tại ST2, đơn A total 1 111 000 hoàn tất (H−1) 23:59:59 +07:00; đơn B total 2 222 000 hoàn tất H 00:00:00 +07:00; ST2 không có đơn khác ngày H−1, H | J35: Kỳ 1: H – H; Kỳ 2: H−1 – H−1; Store: ST2 | K35: 1. Mở menu Dashboard, vào màn hình Dashboard Doanh thu & Đơn hàng 2. Mở bộ chọn Store, chỉ chọn ST2 3. Nhập Từ ngày H, Đến ngày H trên lịch chọn khoảng 4. Nhập Từ ngày H−1, Đến ngày H−1 trên lịch chọn khoảng | L35: 3. Sales = 2 222 000; Transactions = 1 (chỉ đơn B) 4. Sales = 1 111 000; Transactions = 1 (chỉ đơn A) | N35: Not Run | O35: Review R-18 | P35: Blocked (SETUP-03)
A36: TC-SCOPE-023 | B36: 02. Phạm vi dữ liệu & phân quyền | C36: FR-SPM-001 | D36: Kiểm tra truy cập dashboard và API số liệu khi chưa đăng nhập bị chặn | E36: Security | F36: Negative | G36: PERM | H36: P1 | I36: 1. Chưa đăng nhập (xoá cookie phiên) 2. Theo SETUP-09: đã copy URL dashboard và request API số liệu từ một phiên hợp lệ trước đó | J36: URL dashboard; request API số liệu | K36: 1. Mở URL dashboard trên trình duyệt chưa đăng nhập 2. Gửi lại request API số liệu không kèm phiên | L36: 1. Chuyển tới màn hình đăng nhập, không hiển thị số liệu 2. Không trả số liệu (lỗi xác thực) | N36: Not Run | O36: Review R-35; BR-SPM-001 | P36: Ready
A37: TC-SALES-001 | B37: 03. Sales (số đo nền) | C37: FR-SPM-002 | D37: Kiểm tra Sales sau thuế ST1 ngày D = 42 600 000 (đã trừ đơn trả R1) | E37: Functional | F37: Positive | G37: EP | H37: P1 | I37: 1. Theo SETUP-01: đăng nhập U-SM12 2. Theo SETUP-02 | J37: Kỳ: D – D; Store: ST1; bán 48 000 000; trả R1 5 400 000 | K37: 1. Mở menu Dashboard, vào màn hình Dashboard Doanh thu & Đơn hàng 2. Nhập Từ ngày D, Đến ngày D trên lịch chọn khoảng 3. Mở bộ chọn Store, chỉ chọn ST1 4. Đảm bảo đang chọn "Sau thuế", xem thẻ Sales | L37: 4. Thẻ Sales = 42 600 000 (12 525 500 + 10 000 000 + 9 474 500 + 8 000 000 + 8 000 000 − 5 400 000), nhãn Sau thuế | M37: Candidate | N37: Not Run | O37: AC-SPM-002-01 | P37: Ready
A38: TC-SALES-002 | B38: 03. Sales (số đo nền) | C38: FR-SPM-002 | D38: Kiểm tra Sales trước thuế ST1 ngày D = Sales sau thuế − (Σ tax_total đơn bán − Σ tax_total đơn trả) | E38: Functional | F38: Positive | G38: EP | H38: P1 | I38: 1. Theo SETUP-01: đăng nhập U-SM12 2. Theo SETUP-02 3. Theo SETUP-08: đã ghi tax_total của O1, O2, O3, O5, O6, R1 | J38: Kỳ: D – D; Store: ST1 | K38: 1. Mở menu Dashboard, vào màn hình Dashboard Doanh thu & Đơn hàng 2. Nhập Từ ngày D, Đến ngày D trên lịch chọn khoảng 3. Mở bộ chọn Store, chỉ chọn ST1 4. Bấm "Trước thuế", xem thẻ Sales | L38: 4. Thẻ Sales = 42 600 000 − (Σ tax_total O1, O2, O3, O5, O6 − tax_total R1), nhãn Trước thuế; giá trị ≤ 42 600 000 - Không bằng Σ subtotal (không dùng subtotal) | M38: Candidate | N38: Not Run | O38: AC-SPM-002-07, 08; đơn trả: [Cần xác nhận Q-18] | P38: Needs Clarification (Q-18)
A39: TC-SALES-003 | B39: 03. Sales (số đo nền) | C39: FR-SPM-002;FR-SPM-001 | D39: Kiểm tra đơn trả cross-period trừ vào kỳ của ngày trả, kỳ của đơn bán giữ nguyên | E39: Functional | F39: Edge | G39: DT | H39: P1 | I39: 1. Theo SETUP-01: đăng nhập U-SM12 2. Theo SETUP-02 (O0 bán ngày D−1 3 200 000; R2 trả 1 sp O0 ngày D+1 1 600 000) | J39: Store: ST1; Kỳ 1: D−1 – D−1; Kỳ 2: D+1 – D+1 | K39: 1. Mở menu Dashboard, vào màn hình Dashboard Doanh thu & Đơn hàng 2. Mở bộ chọn Store, chỉ chọn ST1 3. Nhập Từ ngày D−1, Đến ngày D−1 trên lịch chọn khoảng 4. Nhập Từ ngày D+1, Đến ngày D+1 trên lịch chọn khoảng | L39: 3. Sales ngày D−1 = 3 200 000 (không bị trừ R2) 4. Sales ngày D+1 = −6 600 000 (gồm −1 600 000 của R2 và −5 000 000 của R3) | M39: Candidate | N39: Not Run | O39: AC-SPM-002-02, BR-SPM-004 | P39: Ready
A40: TC-SALES-004 | B40: 03. Sales (số đo nền) | C40: FR-SPM-002;FR-SPM-009 | D40: Kiểm tra kỳ chỉ có đơn trả hiển thị Sales âm −6 600 000 có dấu − và màu Error | E40: Functional | F40: Edge | G40: EP | H40: P1 | I40: 1. Theo SETUP-01: đăng nhập U-SM12 2. Theo SETUP-02 | J40: Kỳ: D+1 – D+1; Store: ST1 | K40: 1. Mở menu Dashboard, vào màn hình Dashboard Doanh thu & Đơn hàng 2. Nhập Từ ngày D+1, Đến ngày D+1 trên lịch chọn khoảng 3. Mở bộ chọn Store, chỉ chọn ST1 | L40: 3. Thẻ Sales hiển thị −6 600 000 (dấu −, tách nghìn khoảng trắng), chữ màu Error; không hiển thị 0 | M40: Candidate | N40: Not Run | O40: AC-SPM-002-03, AC-SPM-009-05 | P40: Ready
...

Sheet Summary
A1: Tổng hợp — DASHBOARD-DOANH-THU
A3: Status | B3: Số lượng
A4: Blocked | B4: =COUNTIF('Test Cases'!N2:N733,"Blocked") -> 0
A5: Fail | B5: =COUNTIF('Test Cases'!N2:N733,"Fail") -> 0
A6: Not Run | B6: =COUNTIF('Test Cases'!N2:N733,"Not Run") -> 232
A7: Obsolete | B7: =COUNTIF('Test Cases'!N2:N733,"Obsolete") -> 0
A8: Pass | B8: =COUNTIF('Test Cases'!N2:N733,"Pass") -> 0
A9: Skipped | B9: =COUNTIF('Test Cases'!N2:N733,"Skipped") -> 0
A11: Design_Status | B11: Số lượng
A12: Ready | B12: =COUNTIF('Test Cases'!P2:P733,"Ready") -> 134
A13: Needs Clarification | B13: =COUNTIF('Test Cases'!P2:P733,"Needs Clarification*") -> 39
A14: Blocked | B14: =COUNTIF('Test Cases'!P2:P733,"Blocked*") -> 59
A15: Obsolete | B15: =COUNTIF('Test Cases'!P2:P733,"Obsolete") -> 0
A17: Priority | B17: Số lượng
A18: P1 | B18: =COUNTIF('Test Cases'!H2:H733,"P1") -> 56
A19: P2 | B19: =COUNTIF('Test Cases'!H2:H733,"P2") -> 91
A20: P3 | B20: =COUNTIF('Test Cases'!H2:H733,"P3") -> 71
A21: P4 | B21: =COUNTIF('Test Cases'!H2:H733,"P4") -> 14
A23: Scenario | B23: Số lượng
A24: Boundary | B24: =COUNTIF('Test Cases'!F2:F733,"Boundary") -> 39
A25: Edge | B25: =COUNTIF('Test Cases'!F2:F733,"Edge") -> 49
A26: Negative | B26: =COUNTIF('Test Cases'!F2:F733,"Negative") -> 24
A27: Positive | B27: =COUNTIF('Test Cases'!F2:F733,"Positive") -> 120
A29: Test_Type | B29: Số lượng
A30: Accessibility | B30: =COUNTIF('Test Cases'!E2:E733,"Accessibility") -> 3
A31: Compatibility | B31: =COUNTIF('Test Cases'!E2:E733,"Compatibility") -> 2
A32: Functional | B32: =COUNTIF('Test Cases'!E2:E733,"Functional") -> 156
A33: Integration | B33: =COUNTIF('Test Cases'!E2:E733,"Integration") -> 13
A34: Performance | B34: =COUNTIF('Test Cases'!E2:E733,"Performance") -> 3
A35: Security | B35: =COUNTIF('Test Cases'!E2:E733,"Security") -> 10
A36: UI | B36: =COUNTIF('Test Cases'!E2:E733,"UI") -> 39
A37: Usability | B37: =COUNTIF('Test Cases'!E2:E733,"Usability") -> 1
A38: Validation | B38: =COUNTIF('Test Cases'!E2:E733,"Validation") -> 5
A40: Module | B40: Số lượng
A41: 01. Bộ lọc kỳ & thuế | B41: =COUNTIF('Test Cases'!B2:B733,"01. Bộ lọc kỳ & thuế") -> 12
A42: 02. Phạm vi dữ liệu & phân quyền | B42: =COUNTIF('Test Cases'!B2:B733,"02. Phạm vi dữ liệu & phân quyền") -> 23
A43: 03. Sales (số đo nền) | B43: =COUNTIF('Test Cases'!B2:B733,"03. Sales (số đo nền)") -> 17
A44: 04. Transactions | B44: =COUNTIF('Test Cases'!B2:B733,"04. Transactions") -> 4
A45: 05. Frequency | B45: =COUNTIF('Test Cases'!B2:B733,"05. Frequency") -> 5
A46: 06. Coupon % | B46: =COUNTIF('Test Cases'!B2:B733,"06. Coupon %") -> 3
...

Sheet RTM
A1: Req_ID | B1: Mô tả | C1: Số TC | D1: Test cases | E1: Trạng thái
A2: FR-INC-001 | B2: Xác định sản phẩm & Brand từng dòng trên bill | C2: 2 | D2: TC-INC-001, TC-INC-032 | E2: Covered
A3: FR-INC-002 | B3: Discount Threshold Gate theo từng dòng (BR-INC-001) | C3: 8 | D3: TC-INC-002, TC-INC-003, TC-INC-004, TC-INC-005, TC-INC-006, TC-INC-007, TC-INC-008, TC-INC-009 | E3: Covered
A4: FR-INC-003 | B4: Khách có PIC hay không; B2B; chia đều khi không có PIC (BR-INC-002) | C4: 7 | D4: TC-INC-010, TC-INC-011, TC-INC-012, TC-INC-013, TC-INC-014, TC-INC-015, TC-INC-031 | E4: Covered
A5: FR-INC-004 | B5: Tỷ lệ chia theo Brand Config: PIC / Other CA (BR-INC-003, 004) | C5: 12 | D5: TC-INC-015, TC-INC-016, TC-INC-017, TC-INC-018, TC-INC-019, TC-INC-020, TC-INC-021, TC-INC-022, TC-INC-023, TC-INC-024, TC-INC-025, TC-INC-032 | E5: Covered
A6: FR-INC-005 | B6: Tổng hợp Incentive theo nhân viên theo kỳ (BR-INC-005) | C6: 6 | D6: TC-INC-009, TC-INC-012, TC-INC-026, TC-INC-027, TC-INC-028, TC-INC-029 | E6: Covered
A7: FR-SPM-001 | B7: Phạm vi dữ liệu theo Position Rule, kỳ lọc, tập đơn sale_in_scope / return_in_scope (BR-SPM-001, 002) | C7: 23 | D7: TC-SCOPE-001, TC-SCOPE-002, TC-SCOPE-003, TC-SCOPE-004, TC-SCOPE-005, TC-SCOPE-006, TC-SCOPE-007, TC-SCOPE-008, TC-SCOPE-009, TC-SCOPE-010, TC-SCOPE-011, TC-SCOPE-012, TC-SCOPE-013, TC-SCOPE-014, TC-SCOPE-015, TC-SCOPE-016, TC-SCOPE-018, TC-SCOPE-020, TC-SCOPE-021, TC-SCOPE-022, TC-SCOPE-023, TC-SALES-003, TC-TABLE-016 | E7: Covered
A8: FR-SPM-002 | B8: Sales sau thuế / trước thuế (BR-SPM-003, 004, 014) | C8: 17 | D8: TC-SALES-001, TC-SALES-002, TC-SALES-003, TC-SALES-004, TC-SALES-005, TC-SALES-006, TC-SALES-007, TC-SALES-008, TC-SALES-009, TC-SALES-010, TC-SALES-011, TC-SALES-012, TC-SALES-013, TC-SALES-014, TC-SALES-015, TC-SALES-016, TC-SALES-017 | E8: Covered
A9: FR-SPM-003 | B9: Transactions (REQ-BSP-03; BR-SPM-005, 006) | C9: 6 | D9: TC-SCOPE-007, TC-TRX-001, TC-TRX-002, TC-TRX-003, TC-TRX-004, TC-DISP-001 | E9: Covered
A10: FR-SPM-004 | B10: Frequency (REQ-BSP-04; BR-SPM-012) | C10: 6 | D10: TC-FREQ-001, TC-FREQ-002, TC-FREQ-003, TC-FREQ-004, TC-FREQ-005, TC-DISP-001 | E10: Covered
A11: FR-SPM-005 | B11: Coupon % (REQ-BSP-05; BR-SPM-008, 008a) | C11: 4 | D11: TC-CPN-001, TC-CPN-002, TC-CPN-003, TC-DISP-001 | E11: Covered
A12: FR-SPM-006 | B12: AOV sau thuế / trước thuế (REQ-BSP-06; BR-SPM-009, 010) | C12: 7 | D12: TC-AOV-001, TC-AOV-002, TC-AOV-003, TC-AOV-004, TC-AOV-005, TC-AOV-006, TC-AOV-007 | E12: Covered
A13: FR-SPM-007 | B13: UPT (REQ-BSP-07; BR-SPM-011) | C13: 6 | D13: TC-UPT-001, TC-UPT-002, TC-UPT-003, TC-UPT-004, TC-UPT-005, TC-DISP-001 | E13: Covered
... A17: FR-SPM-011 | B17: Hiển thị quy mô ~100 store: bộ chọn store, lọc Client Advisor, xếp hạng Top/Bottom, bảng breakdown (BR-SPM-020…023) | C17: 39 | D17: TC-SCOPE-015, TC-SCOPE-017, TC-SCOPE-021, TC-CHART-049, TC-STORE-001, TC-STORE-002, TC-STORE-003, TC-STORE-004, TC-STORE-005, TC-STORE-006, TC-STORE-007, TC-STORE-008, TC-STORE-009, TC-STORE-010, TC-STORE-011, TC-STORE-012, TC-RANK-001, TC-RANK-002, TC-RANK-003, TC-RANK-004, TC-RANK-005, TC-RANK-006, TC-TABLE-001, TC-TABLE-002, TC-TABLE-003, TC-TABLE-004, TC-TABLE-005, TC-TABLE-006, TC-TABLE-007, TC-TABLE-008, TC-TABLE-009, TC-TABLE-010, TC-TABLE-011, TC-TABLE-013, TC-TABLE-014, TC-TABLE-015, TC-TABLE-016, TC-TABLE-017, TC-TABLE-018 | E17: Covered
A18: NFR-INC-001 | B18: Điều chỉnh Incentive khi bill bị huỷ/hoàn trả | C18: 0 | E18: N/A
A19: NFR-INC-002 | B19: Incentive truy vết được về đúng bill/dòng gốc từ HUB | C19: 1 | D19: TC-INC-030 | E19: Covered
A20: NFR-SPM-006 | B20: Chọn store, tìm kiếm, sắp xếp, phân trang, đổi thuế phản hồi dưới 400ms | C20: 3 | D20: TC-NFR-001, TC-NFR-002, TC-NFR-003 | E20: Covered
A21: REQ-MIG-01 | B21: Định dạng JSONL migrate dữ liệu hoa hồng: bỏ qua đơn trả, bung salerep_ids, giá trị theo dòng đơn | C21: 3 | D21: TC-MIG-001, TC-MIG-002, TC-MIG-003 | E21: Covered
A22: REQ-UI-01 | B22: Bộ lọc Kỳ xem (5 preset) + Từ ngày – Đến ngày (lịch chọn khoảng, tối đa 366 ngày, báo lỗi giữ kỳ cũ) | C22: 10 | D22: TC-FLT-001, TC-FLT-002, TC-FLT-003, TC-FLT-004, TC-FLT-005, TC-FLT-006, TC-FLT-007, TC-FLT-008, TC-FLT-009, TC-FLT-010 | E22: Covered
A23: REQ-UI-02 | B23: Bộ chuyển Giá trị tiền Sau thuế/Trước thuế; thẻ KPI tiền có nhãn thuế, số đầy đủ, dòng phụ số còn lại, icon i | C23: 7 | D23: TC-FLT-001, TC-FLT-011, TC-DISP-007, TC-DISP-008, TC-DISP-009, TC-DISP-010, TC-DISP-011 | E23: Covered
A24: REQ-UI-03 | B24: Cảnh báo động: đơn trả cross-period; đơn VAT = 0 khi xem trước thuế | C24: 5 | D24: TC-ALERT-001, TC-ALERT-002, TC-ALERT-003, TC-ALERT-004, TC-ALERT-005 | E24: Covered
A25: REQ-UI-04 | B25: Hai nhóm thẻ KPI: Doanh thu và giao dịch (4 thẻ), Chỉ số bình quân (4 thẻ) | C25: 1 | D25: TC-DISP-013 | E25: Covered
A26: REQ-UI-05 | B26: Vai trò Cá nhân: chỉ biểu đồ thời gian, không xếp hạng; bảng thay bằng thẻ giải thích | C26: 1 | D26: TC-SCOPE-017 | E26: Covered
A27: REQ-UI-06 | B27: Hover state, focus ring, tooltip hiện cả khi focus bàn phím | C27: 3 | D27: TC-NFR-006, TC-NFR-007, TC-NFR-008 | E27: Covered
A28: REQ-UI-07 | B28: Breakpoint ≥1280px; 768–1279px thu sidebar về icon, KPI 2 cột, biểu đồ 1 cột | C28: 2 | D28: TC-NFR-004, TC-NFR-005 | E28: Covered

Sheet Conditions
A1: Cond_ID | B1: Req_ID | C1: Điều kiện kiểm thử | D1: Kỹ thuật | E1: Test cases | F1: Trạng thái
A2: CO-01 | B2: REQ-UI-01; REQ-UI-02 | C2: Khối bộ lọc có đủ 5 preset, Từ ngày – Đến ngày, Store, Client Advisor, Giá trị tiền | D2: CL | E2: TC-FLT-001 | F2: Covered
A3: CO-02 | B3: REQ-UI-01 | C3: Preset Hôm nay → kỳ 1 ngày là hôm nay | D3: EP | E3: TC-FLT-002 | F3: Covered
A4: CO-03 | B4: REQ-UI-01 | C4: Preset Tuần này → Thứ Hai tuần hiện tại đến hôm nay | D4: EP | E4: TC-FLT-003 | F4: Covered
A5: CO-04 | B5: REQ-UI-01 | C5: Preset Tháng này → ngày 01 đến hôm nay | D5: EP | E5: TC-FLT-004 | F5: Covered
A6: CO-05 | B6: REQ-UI-01 | C6: Preset Tháng trước → trọn tháng dương lịch trước | D6: EP | E6: TC-FLT-005 | F6: Covered
A7: CO-06 | B7: REQ-UI-01 | C7: Preset Năm này → 01/01 đến hôm nay | D7: EP | E7: TC-FLT-006 | F7: Covered
A8: CO-07 | B8: REQ-UI-01 | C8: Chọn khoảng Từ ngày – Đến ngày hợp lệ → mọi khối tính theo kỳ mới | D8: EP | E8: TC-FLT-007 | F8: Covered
A9: CO-08 | B9: REQ-UI-01 | C9: Khoảng 366 ngày (biên trên) được chấp nhận | D9: BVA | E9: TC-FLT-008 | F9: Covered
A10: CO-09 | B10: REQ-UI-01 | C10: Khoảng 367 ngày bị chặn: báo lỗi, giữ kỳ cũ | D10: BVA | E10: TC-FLT-009 | F10: Covered
A11: CO-10 | B11: REQ-UI-01 | C11: Kỳ mặc định khi mở dashboard | D11: EP | E11: TC-FLT-010 | F11: Covered
A12: CO-11 | B12: REQ-UI-02 | C12: Cách nhìn thuế mặc định khi mở dashboard | D12: EP | E12: TC-FLT-011 | F12: Covered
... A145: CO-144 | B145: FR-SPM-010; FR-SPM-011 | C145: Biểu đồ theo Store/Client Advisor đang lọc | D145: EP | E145: TC-CHART-049 | F145: Covered
A146: CO-145 | B146: FR-SPM-010 | C146: Bấm vào đơn vị đang được tự chọn | D146: ST | F146: Pending
A147: CO-146 | B147: FR-SPM-010 | C147: Kỳ chạm 14 tháng lịch | D147: BVA | F147: N/A
A148: CO-147 | B148: FR-SPM-011 | C148: CRM: mặc định Toàn Tam Sơn · N store; lọc CA bị khoá | D148: EP | E148: TC-STORE-001 | F148: Covered
A149: CO-148 | B149: FR-SPM-011 | C149: Retail Manager Hermès: mặc định chỉ store Hermès, không thêm được store ngoài | D149: PERM | E149: TC-STORE-002 | F149: Covered
A150: CO-149 | B150: FR-SPM-011 | C150: Chip Brand Hermès → chỉ store Hermès được chọn, nhãn nút | D150: EP | E150: TC-STORE-003 | F150: Covered
A151: CO-150 | B151: FR-SPM-011 | C151: Tìm store theo tên và theo Brand | D151: EP | E151: TC-STORE-004 | F151: Covered
A152: CO-151 | B152: FR-SPM-011 | C152: Không bỏ được store cuối cùng | D152: BVA | E152: TC-STORE-005 | F152: Covered
A153: CO-152 | B153: FR-SPM-011 | C153: Chọn 1 store → nhãn là tên store | D153: EP | E153: TC-STORE-005 | F153: Covered
A154: CO-153 | B154: FR-SPM-011 | C154: Chọn 3 store → nhãn 3 store đã chọn | D154: EP | E154: TC-STORE-006 | F154: Covered
A155: CO-154 | B155: FR-SPM-011 | C155: Nút chọn tất cả và bộ đếm đã chọn / tổng | D155: CL | E155: TC-STORE-007 | F155: Covered
A156: CO-155 | B156: FR-SPM-011 | C156: Thu hẹp ST1 + ST2 → ST1: KPI, biểu đồ, bảng tính lại | D156: EP | E156: TC-STORE-008 | F156: Covered
A157: CO-156 | B157: FR-SPM-011 | C157: 6 store → lọc CA khoá + gợi ý | D157: BVA | E157: TC-STORE-009 | F157: Covered
A158: CO-157 | B158: FR-SPM-011 | C158: 5 store → lọc CA mở, liệt kê CA kèm tên store | D158: BVA | E158: TC-STORE-010 | F158: Covered
A159: CO-158 | B159: FR-SPM-011 | C159: Chọn CA-A → số liệu chỉ bill CA-A đứng tên | D159: EP | E159: TC-STORE-011 | F159: Covered
A160: CO-159 | B160: FR-SPM-011 | C160: Đang lọc CA rồi chọn thêm store vượt 5 | D160: ST | F160: Pending
A161: CO-160 | B161: FR-SPM-011 | C161: Top 10: hạng 1–10 giảm dần theo Sales, có Brand | D161: EP | E161: TC-RANK-001 | F161: Covered
A162: CO-161 | B162: FR-SPM-011 | C162: Bottom 10: hạng thực N…N−9 tăng dần từ thấp | D162: EP | E162: TC-RANK-002 | F162: Covered
A163: CO-162 | B163: FR-SPM-011 | C163: Xếp hạng theo cách nhìn thuế đang chọn | D163: EP | E163: TC-RANK-003 | F163: Covered
A164: CO-163 | B164: FR-SPM-011 | C164: Store không phát sinh trong kỳ không được xếp hạng | D164: EP | E164: TC-RANK-004 | F164: Covered
A165: CO-164 | B165: FR-SPM-011 | C165: Store Sales âm (chỉ đơn trả) vẫn được xếp hạng ở cuối | D165: EG | E165: TC-RANK-005 | F165: Covered
A166: CO-165 | B166: FR-SPM-011 | C166: 1 store → xếp hạng Client Advisor | D166: EP | E166: TC-RANK-006 | F166: Covered
A167: CO-166 | B167: FR-SPM-011 | C167: Hai store cùng Sales: thứ tự hạng | D167: EG | F167: Pending
A168: CO-167 | B168: FR-SPM-011 | C168: CRM: tab Theo Store mặc định, trang 1, 15 dòng, từ–đến / tổng | D168: EP | E168: TC-TABLE-001 | F168: Covered
A169: CO-168 | B169: FR-SPM-011 | C169: Đổi 30, 50 dòng/trang | D169: EP | E169: TC-TABLE-002 | F169: Covered
A170: CO-169 | B170: FR-SPM-011 | C170: Trang cuối hiển thị phần còn lại | D170: BVA | E170: TC-TABLE-003 | F170: Covered
A171: CO-170 | B171: FR-SPM-011 | C171: Tìm kiếm: cột # giữ hạng thực | D171: EP | E171: TC-TABLE-004 | F171: Covered
A172: CO-171 | B172: FR-SPM-011 | C172: Tìm kiếm + đổi trang: dòng Tổng không đổi | D172: EP | E172: TC-TABLE-005 | F172: Covered
...

Sheet Clauses
A1: Clause_ID | B1: Req_ID | C1: Mệnh đề | D1: CO | E1: Test cases | F1: Trạng thái
A2: REQ-UI-01-c1 | B2: REQ-UI-01 | C2: REQ-UI-01-c1 | D2: CO-01; CO-02; CO-03; CO-04; CO-05; CO-06 | E2: TC-FLT-001, TC-FLT-002, TC-FLT-003, TC-FLT-004, TC-FLT-005, TC-FLT-006 | F2: Covered
A3: REQ-UI-01-c2 | B3: REQ-UI-01 | C3: REQ-UI-01-c2 | D3: CO-07 | E3: TC-FLT-007 | F3: Covered (oracle tạm)
A4: REQ-UI-01-c3 | B4: REQ-UI-01 | C4: REQ-UI-01-c3 | D4: CO-08; CO-09 | E4: TC-FLT-008, TC-FLT-009 | F4: Covered
A5: REQ-UI-01-c4 | B5: REQ-UI-01 | C5: REQ-UI-01-c4 | D5: CO-09 | E5: TC-FLT-009 | F5: Covered (oracle tạm)
A6: REQ-UI-01-c5 | B6: REQ-UI-01 | C6: REQ-UI-01-c5 | D6: CO-10 | E6: TC-FLT-010 | F6: Covered (oracle tạm)
A7: REQ-UI-01-c6 | B7: REQ-UI-01 | C7: REQ-UI-01-c6 | F7: Pending
A8: REQ-UI-02-c1 | B8: REQ-UI-02 | C8: REQ-UI-02-c1 | D8: CO-01; CO-11 | E8: TC-FLT-001, TC-FLT-011 | F8: Covered
A9: REQ-UI-02-c2 | B9: REQ-UI-02 | C9: REQ-UI-02-c2 | D9: CO-85 | E9: TC-DISP-007 | F9: Covered
A10: REQ-UI-02-c3 | B10: REQ-UI-02 | C10: REQ-UI-02-c3 | D10: CO-86 | E10: TC-DISP-008 | F10: Covered
A11: REQ-UI-02-c4 | B11: REQ-UI-02 | C11: REQ-UI-02-c4 | D11: CO-87 | E11: TC-DISP-009 | F11: Covered
A12: REQ-UI-02-c5 | B12: REQ-UI-02 | C12: REQ-UI-02-c5 | D12: CO-88 | E12: TC-DISP-010 | F12: Covered
A13: REQ-UI-02-c6 | B13: REQ-UI-02 | C13: REQ-UI-02-c6 | D13: CO-89 | E13: TC-DISP-011 | F13: Covered
A14: REQ-UI-03-c1 | B14: REQ-UI-03 | C14: REQ-UI-03-c1 | D14: CO-92; CO-93 | E14: TC-ALERT-001, TC-ALERT-002 | F14: Covered (oracle tạm)
A15: REQ-UI-03-c3 | B15: REQ-UI-03 | C15: REQ-UI-03-c3 | D15: CO-237 | E15: TC-ALERT-005 | F15: Covered (oracle tạm)
A16: REQ-UI-03-c2 | B16: REQ-UI-03 | C16: REQ-UI-03-c2 | D16: CO-94; CO-95 | E16: TC-ALERT-003, TC-ALERT-004 | F16: Covered (oracle tạm)
A17: REQ-UI-04-c1 | B17: REQ-UI-04 | C17: REQ-UI-04-c1 | D17: CO-91 | E17: TC-DISP-013 | F17: Covered
A18: REQ-UI-04-c2 | B18: REQ-UI-04 | C18: REQ-UI-04-c2 | D18: CO-91 | E18: TC-DISP-013 | F18: Covered
A19: REQ-UI-05-c1 | B19: REQ-UI-05 | C19: REQ-UI-05-c1 | D19: CO-29 | E19: TC-SCOPE-017 | F19: Covered
... A30: FR-SPM-001-c1b | B30: FR-SPM-001 | C30: FR-SPM-001-c1b | D30: CO-230 | E30: TC-SCOPE-020 | F30: Covered
A31: FR-SPM-001-c1c | B31: FR-SPM-001 | C31: FR-SPM-001-c1c | F31: Pending
A32: FR-SPM-001-c15 | B32: FR-SPM-001 | C32: FR-SPM-001-c15 | D32: CO-231 | E32: TC-SCOPE-021 | F32: Covered
A33: FR-SPM-001-c16 | B33: FR-SPM-001 | C33: FR-SPM-001-c16 | F33: Pending
A34: FR-SPM-001-c2 | B34: FR-SPM-001 | C34: FR-SPM-001-c2 | D34: CO-13 | E34: TC-SCOPE-001 | F34: Covered
A35: FR-SPM-001-c3 | B35: FR-SPM-001 | C35: FR-SPM-001-c3 | D35: CO-14 | E35: TC-SCOPE-002 | F35: Covered
A36: FR-SPM-001-c4 | B36: FR-SPM-001 | C36: FR-SPM-001-c4 | D36: CO-17 | E36: TC-SCOPE-005 | F36: Covered (oracle tạm)
A37: FR-SPM-001-c5 | B37: FR-SPM-001 | C37: FR-SPM-001-c5 | D37: CO-18; CO-148 | E37: TC-SCOPE-006, TC-STORE-002 | F37: Covered
A38: FR-SPM-001-c6 | B38: FR-SPM-001 | C38: FR-SPM-001-c6 | D38: CO-19 | E38: TC-SCOPE-007 | F38: Covered
A39: FR-SPM-001-c7 | B39: FR-SPM-001 | C39: FR-SPM-001-c7 | D39: CO-20 | E39: TC-SCOPE-008 | F39: Covered
A40: FR-SPM-001-c8 | B40: FR-SPM-001 | C40: FR-SPM-001-c8 | D40: CO-34 | E40: TC-SALES-003 | F40: Covered
A41: FR-SPM-001-c9 | B41: FR-SPM-001 | C41: FR-SPM-001-c9 | D41: CO-21 | E41: TC-SCOPE-009 | F41: Covered (oracle tạm)
A42: FR-SPM-001-c10 | B42: FR-SPM-001 | C42: FR-SPM-001-c10 | D42: CO-22 | E42: TC-SCOPE-010 | F42: Covered (oracle tạm)
A43: FR-SPM-001-c11 | B43: FR-SPM-001 | C43: FR-SPM-001-c11 | D43: CO-23; CO-24; CO-232 | E43: TC-SCOPE-011, TC-SCOPE-012, TC-SCOPE-022 | F43: Covered (oracle tạm)
A44: FR-SPM-001-c17 | B44: FR-SPM-001 | C44: FR-SPM-001-c17 | D44: CO-233 | E44: TC-SCOPE-023 | F44: Covered
A45: FR-SPM-001-c12 | B45: FR-SPM-001 | C45: FR-SPM-001-c12 | D45: CO-25; CO-26; CO-27 | E45: TC-SCOPE-013, TC-SCOPE-014, TC-SCOPE-015 | F45: Covered
... A79: FR-SPM-005-c6 | B79: FR-SPM-005 | C79: FR-SPM-005-c6 | D79: CO-59 | E79: TC-CPN-003 | F79: Covered
A80: FR-SPM-005-c7 | B80: FR-SPM-005 | C80: FR-SPM-005-c7 | F80: Pending
A81: FR-SPM-006-c1 | B81: FR-SPM-006 | C81: FR-SPM-006-c1 | D81: CO-60 | E81: TC-AOV-001 | F81: Covered
A82: FR-SPM-006-c2 | B82: FR-SPM-006 | C82: FR-SPM-006-c2 | D82: CO-61 | E82: TC-AOV-002 | F82: Covered
A83: FR-SPM-006-c3 | B83: FR-SPM-006 | C83: FR-SPM-006-c3 | D83: CO-62 | E83: TC-AOV-003 | F83: Covered
...
